Workbook

Sheet Reformatted
A1: Plate_Number | B1: Vessel_Name | C1: Elapsed | D1: P20 LIN1-0B-b1 (A1), Image 1 | E1: P20 LIN1-0B-b1 (A1), Image 2 | F1: P20 LIN1-0B-b1 (A1), Image 3 | G1: P20 LIN1-0B-b1 (A1), Image 4 | H1: P20 LIN1-0B-b1 (A1), Image 5 | I1: P20 LIN1-0B-b1 (A1), Image 6 | J1: P20 LIN1-0B-b1 (A1), Image 7 | K1: P20 LIN1-0B-b1 (A1), Image 8 | L1: P20 LIN1-0B-b1 (A1), Image 9 | M1: P20 LIN1-0B-b1 (B1), Image 1 | N1: P20 LIN1-0B-b1 (B1), Image 2 | O1: P20 LIN1-0B-b1 (B1), Image 3 | P1: P20 LIN1-0B-b1 (B1), Image 4 | Q1: P20 LIN1-0B-b1 (B1), Image 5 | R1: P20 LIN1-0B-b1 (B1), Image 6 | S1: P20 LIN1-0B-b1 (B1), Image 7 | T1: P20 LIN1-0B-b1 (B1), Image 8 | U1: P20 LIN1-0B-b1 (B1), Image 9 | V1: P17 LIN2-0A-b1 (A2), Image 1 | W1: P17 LIN2-0A-b1 (A2), Image 2 | X1: P17 LIN2-0A-b1 (A2), Image 3 | Y1: P17 LIN2-0A-b1 (A2), Image 4 | Z1: P17 LIN2-0A-b1 (A2), Image 5 | AA1: P17 LIN2-0A-b1 (A2), Image 6 | AB1: P17 LIN2-0A-b1 (A2), Image 7 | AC1: P17 LIN2-0A-b1 (A2), Image 8 | AD1: P17 LIN2-0A-b1 (A2), Image 9 | AE1: P17 LIN2-0A-b1 (B2), Image 1 | AF1: P17 LIN2-0A-b1 (B2), Image 2 | AG1: P17 LIN2-0A-b1 (B2), Image 3 | AH1: P17 LIN2-0A-b1 (B2), Image 4 | AI1: P17 LIN2-0A-b1 (B2), Image 5 | AJ1: P17 LIN2-0A-b1 (B2), Image 6 | AK1: P17 LIN2-0A-b1 (B2), Image 7 | AL1: P17 LIN2-0A-b1 (B2), Image 8 | AM1: P17 LIN2-0A-b1 (B2), Image 9 | AN1: P14 LIN3-0A-b2 (A3), Image 1 | AO1: P14 LIN3-0A-b2 (A3), Image 2 | AP1: P14 LIN3-0A-b2 (A3), Image 3 | AQ1: P14 LIN3-0A-b2 (A3), Image 4 | AR1: P14 LIN3-0A-b2 (A3), Image 5 | AS1: P14 LIN3-0A-b2 (A3), Image 6 | AT1: P14 LIN3-0A-b2 (A3), Image 7 | AU1: P14 LIN3-0A-b2 (A3), Image 8 | AV1: P14 LIN3-0A-b2 (A3), Image 9 | AW1: P14 LIN3-0A-b2 (B3), Image 1 | AX1: P14 LIN3-0A-b2 (B3), Image 2 | AY1: P14 LIN3-0A-b2 (B3), Image 3 | AZ1: P14 LIN3-0A-b2 (B3), Image 4 | BA1: P14 LIN3-0A-b2 (B3), Image 5 | BB1: P14 LIN3-0A-b2 (B3), Image 6 | BC1: P14 LIN3-0A-b2 (B3), Image 7 | BD1: P14 LIN3-0A-b2 (B3), Image 8 | BE1: P14 LIN3-0A-b2 (B3), Image 9 | BF1: P12 LIN4-0B-b2 (A4), Image 1 | BG1: P12 LIN4-0B-b2 (A4), Image 2 | BH1: P12 LIN4-0B-b2 (A4), Image 3 | BI1: P12 LIN4-0B-b2 (A4), Image 4 | BJ1: P12 LIN4-0B-b2 (A4), Image 5 | BK1: P12 LIN4-0B-b2 (A4), Image 6 | BL1: P12 LIN4-0B-b2 (A4), Image 7 | BM1: P12 LIN4-0B-b2 (A4), Image 8 | BN1: P12 LIN4-0B-b2 (A4), Image 9 | BO1: P12 LIN4-0B-b2 (B4), Image 1 | BP1: P12 LIN4-0B-b2 (B4), Image 2 | BQ1: P12 LIN4-0B-b2 (B4), Image 3 | BR1: P12 LIN4-0B-b2 (B4), Image 4 | BS1: P12 LIN4-0B-b2 (B4), Image 5 | BT1: P12 LIN4-0B-b2 (B4), Image 6 | BU1: P12 LIN4-0B-b2 (B4), Image 7 | BV1: P12 LIN4-0B-b2 (B4), Image 8 | BW1: P12 LIN4-0B-b2 (B4), Image 9 | BX1: C1, Image 1 | BY1: C1, Image 2 | BZ1: C1, Image 3 | CA1: C1, Image 4 | CB1: C1, Image 5 | CC1: C1, Image 6 | CD1: C1, Image 7 | CE1: C1, Image 8 | CF1: C1, Image 9 | CG1: C2, Image 1 | CH1: C2, Image 2 | CI1: C2, Image 3 | CJ1: C2, Image 4 | CK1: C2, Image 5 | CL1: C2, Image 6 | CM1: C2, Image 7 | CN1: C2, Image 8 | CO1: C2, Image 9 | CP1: P10 LIN5-0B-b3 (C3), Image 1 | CQ1: P10 LIN5-0B-b3 (C3), Image 2 | CR1: P10 LIN5-0B-b3 (C3), Image 3 | CS1: P10 LIN5-0B-b3 (C3), Image 4 | CT1: P10 LIN5-0B-b3 (C3), Image 5 | CU1: P10 LIN5-0B-b3 (C3), Image 6 | CV1: P10 LIN5-0B-b3 (C3), Image 7 | CW1: P10 LIN5-0B-b3 (C3), Image 8 | CX1: P10 LIN5-0B-b3 (C3), Image 9 | CY1: P10 LIN5-0B-b3 (C4), Image 1 | CZ1: P10 LIN5-0B-b3 (C4), Image 2 | DA1: P10 LIN5-0B-b3 (C4), Image 3 | DB1: P10 LIN5-0B-b3 (C4), Image 4 | DC1: P10 LIN5-0B-b3 (C4), Image 5 | DD1: P10 LIN5-0B-b3 (C4), Image 6 | DE1: P10 LIN5-0B-b3 (C4), Image 7 | DF1: P10 LIN5-0B-b3 (C4), Image 8 | DG1: P10 LIN5-0B-b3 (C4), Image 9
A2: 1 | B2: AS_MRC-5_20240313 | C2: 0 | D2: 15.90103 | E2: 19.93151 | F2: 20.28545 | G2: 20.81676 | H2: 47.85163 | I2: 21.15876 | J2: 26.94555 | K2: 30.41998 | L2: 17.48163 | M2: 20.07027 | N2: 20.81615 | O2: 26.13814 | P2: 22.39961 | Q2: 50.69296 | R2: 19.77294 | S2: 23.76619 | T2: 24.17804 | U2: 17.18272 | V2: 23.49814 | W2: 26.78881 | X2: 27.14475 | Y2: 29.04877 | Z2: 73.49908 | AA2: 25.32117 | AB2: 22.79228 | AC2: 29.01407 | AD2: 25.15666 | AE2: 12.60817 | AF2: 11.77113 | AG2: 15.2356 | AH2: 14.96182 | AI2: 38.46038 | AJ2: 18.08505 | AK2: 18.65507 | AL2: 14.74008 | AM2: 8.990863 | AN2: 17.66772 | AO2: 18.49432 | AP2: 21.86967 | AQ2: 26.64261 | AR2: 39.86868 | AS2: 28.02461 | AT2: 23.29259 | AU2: 24.98791 | AV2: 30.37547 | AW2: 22.45848 | AX2: 21.50698 | AY2: 23.03287 | AZ2: 19.9692 | BA2: 29.57639 | BB2: 17.9189 | BC2: 21.10618 | BD2: 18.7149 | BE2: 14.79553 | BF2: 22.84739 | BG2: 26.55055 | BH2: 22.74919 | BI2: 26.70516 | BJ2: 48.28726 | BK2: 28.0171 | BL2: 28.34496 | BM2: 28.61546 | BN2: 28.15812 | BO2: 11.77188 | BP2: 12.69798 | BQ2: 13.96368 | BR2: 15.91981 | BS2: 25.96393 | BT2: 12.34211 | BU2: 16.21449 | BV2: 13.91212 | BW2: 8.73511 | BX2: 23.25844 | BY2: 23.44248 | BZ2: 21.90641 | CA2: 14.89121 | CB2: 42.45267 | CC2: 22.45431 | CD2: 17.699 | CE2: 25.67874 | CF2: 16.62499 | CG2: 30.9429 | CH2: 26.47884 | CI2: 27.42522 | CJ2: 30.40127 | CK2: 70.09848 | CL2: 29.15619 | CM2: 35.37184 | CN2: 27.48347 | CO2: 22.27334 | CP2: 24.56485 | CQ2: 26.32034 | CR2: 28.64476 | CS2: 29.66257 | CT2: 44.71242 | CU2: 28.83201 | CV2: 24.74206 | CW2: 21.56564 | CX2: 17.59704 | CY2: 17.47712 | CZ2: 24.4215 | DA2: 33.82525 | DB2: 26.85103 | DC2: 35.8242 | DD2: 23.74823 | DE2: 26.88886 | DF2: 25.71194 | DG2: 20.37663
A3: 1 | B3: AS_MRC-5_20240313 | C3: 4 | D3: 13.70022 | E3: 17.71607 | F3: 17.29635 | G3: 18.0421 | H3: 49.06632 | I3: 21.10447 | J3: 25.14034 | K3: 30.41958 | L3: 16.75494 | M3: 13.8859 | N3: 16.50131 | O3: 23.56493 | P3: 16.36719 | Q3: 47.0529 | R3: 19.50612 | S3: 19.66264 | T3: 19.62071 | U3: 15.06173 | V3: 26.04649 | W3: 34.12355 | X3: 32.87054 | Y3: 33.62585 | Z3: 88.87537 | AA3: 31.9327 | AB3: 30.24045 | AC3: 36.37989 | AD3: 32.00196 | AE3: 11.09976 | AF3: 10.27009 | AG3: 14.12894 | AH3: 12.36232 | AI3: 40.11514 | AJ3: 16.26912 | AK3: 17.13853 | AL3: 13.66013 | AM3: 8.406221 | AN3: 19.24333 | AO3: 19.17258 | AP3: 22.95427 | AQ3: 27.71696 | AR3: 44.26478 | AS3: 29.49635 | AT3: 22.32948 | AU3: 24.97582 | AV3: 30.44594 | AW3: 21.5821 | AX3: 21.09846 | AY3: 26.48943 | AZ3: 22.4636 | BA3: 36.63359 | BB3: 19.31545 | BC3: 21.85437 | BD3: 20.11111 | BE3: 15.72443 | BF3: 29.81657 | BG3: 30.10803 | BH3: 25.38646 | BI3: 30.48234 | BJ3: 56.89269 | BK3: 33.86807 | BL3: 34.944 | BM3: 35.85555 | BN3: 34.74767 | BO3: 12.63877 | BP3: 13.04606 | BQ3: 11.99943 | BR3: 15.47414 | BS3: 25.28464 | BT3: 13.66914 | BU3: 17.17951 | BV3: 13.41565 | BW3: 8.704449 | BX3: 21.26106 | BY3: 20.38345 | BZ3: 18.48701 | CA3: 12.48177 | CB3: 36.65121 | CC3: 18.43593 | CD3: 13.40649 | CE3: 19.27277 | CF3: 12.53504 | CG3: 34.54189 | CH3: 33.24826 | CI3: 32.22956 | CJ3: 33.55797 | CK3: 82.52527 | CL3: 27.92484 | CM3: 40.67048 | CN3: 27.05959 | CO3: 25.38147 | CP3: 22.46742 | CQ3: 24.93806 | CR3: 26.65019 | CS3: 25.73174 | CT3: 46.9784 | CU3: 28.09843 | CV3: 22.16114 | CW3: 19.36441 | CX3: 15.45249 | CY3: 14.7967 | CZ3: 23.98847 | DA3: 32.30291 | DB3: 24.50298 | DC3: 36.446 | DD3: 25.45489 | DE3: 23.20039 | DF3: 21.77953 | DG3: 18.32537
A4: 1 | B4: AS_MRC-5_20240313 | C4: 8 | D4: 14.63772 | E4: 18.37515 | F4: 17.04634 | G4: 19.79151 | H4: 48.51118 | I4: 20.22099 | J4: 26.844 | K4: 31.50288 | L4: 17.63324 | M4: 15.98646 | N4: 14.54928 | O4: 22.41737 | P4: 16.99205 | Q4: 41.69014 | R4: 20.00321 | S4: 19.56396 | T4: 19.57619 | U4: 16.01514 | V4: 26.82282 | W4: 33.68034 | X4: 34.21123 | Y4: 37.13026 | Z4: 90.44067 | AA4: 33.8017 | AB4: 32.72475 | AC4: 37.61766 | AD4: 30.75694 | AE4: 12.27505 | AF4: 11.23142 | AG4: 15.05928 | AH4: 12.68425 | AI4: 45.02916 | AJ4: 15.84612 | AK4: 18.73504 | AL4: 12.68432 | AM4: 8.255984 | AN4: 22.9708 | AO4: 23.38888 | AP4: 23.03137 | AQ4: 31.87221 | AR4: 50.77913 | AS4: 31.89719 | AT4: 26.82672 | AU4: 27.56515 | AV4: 33.18618 | AW4: 23.77049 | AX4: 23.33568 | AY4: 30.28334 | AZ4: 24.92344 | BA4: 41.09676 | BB4: 22.0109 | BC4: 25.00307 | BD4: 22.42249 | BE4: 18.49172 | BF4: 30.91107 | BG4: 30.49634 | BH4: 27.43703 | BI4: 32.97735 | BJ4: 63.57182 | BK4: 35.6922 | BL4: 36.92464 | BM4: 39.12806 | BN4: 38.223 | BO4: 13.95597 | BP4: 15.79395 | BQ4: 15.95 | BR4: 15.77415 | BS4: 29.26614 | BT4: 15.11029 | BU4: 18.70622 | BV4: 13.33424 | BW4: 9.710513 | BX4: 20.90581 | BY4: 20.38639 | BZ4: 19.31593 | CA4: 14.90193 | CB4: 35.70824 | CC4: 18.18905 | CD4: 14.88363 | CE4: 19.30623 | CF4: 12.47801 | CG4: 38.17984 | CH4: 34.93826 | CI4: 31.18273 | CJ4: 35.55923 | CK4: 84.26914 | CL4: 36.14893 | CM4: 40.58013 | CN4: 28.09071 | CO4: 26.33952 | CP4: 25.70872 | CQ4: 28.2303 | CR4: 29.1803 | CS4: 28.79541 | CT4: 53.08449 | CU4: 31.73057 | CV4: 24.63512 | CW4: 22.44311 | CX4: 18.82457 | CY4: 16.54188 | CZ4: 25.78643 | DA4: 31.80896 | DB4: 26.6833 | DC4: 39.44445 | DD4: 29.67746 | DE4: 28.86678 | DF4: 23.6451 | DG4: 22.01076
A5: 1 | B5: AS_MRC-5_20240313 | C5: 12 | D5: 13.1321 | E5: 18.82389 | F5: 19.81971 | G5: 19.82674 | H5: 52.07235 | I5: 22.60878 | J5: 27.27046 | K5: 34.55733 | L5: 18.27551 | M5: 16.35237 | N5: 15.53281 | O5: 23.1795 | P5: 17.30305 | Q5: 44.94428 | R5: 22.29636 | S5: 20.22843 | T5: 21.27199 | U5: 18.49002 | V5: 30.22337 | W5: 38.09939 | X5: 34.83596 | Y5: 37.6958 | Z5: 93.16699 | AA5: 37.58891 | AB5: 35.80153 | AC5: 42.5101 | AD5: 35.43974 | AE5: 13.90795 | AF5: 13.56329 | AG5: 17.52322 | AH5: 13.80408 | AI5: 48.97843 | AJ5: 19.05547 | AK5: 20.11588 | AL5: 17.15288 | AM5: 9.178322 | AN5: 25.65819 | AO5: 24.86977 | AP5: 29.27529 | AQ5: 34.91095 | AR5: 57.40759 | AS5: 38.10451 | AT5: 26.49223 | AU5: 27.90469 | AV5: 36.94001 | AW5: 27.41614 | AX5: 25.39199 | AY5: 30.84503 | AZ5: 26.98842 | BA5: 45.75257 | BB5: 24.75968 | BC5: 26.17338 | BD5: 26.18184 | BE5: 20.18985 | BF5: 33.89183 | BG5: 36.76286 | BH5: 32.36499 | BI5: 36.68132 | BJ5: 69.7702 | BK5: 41.09027 | BL5: 42.05351 | BM5: 44.63737 | BN5: 40.96345 | BO5: 17.17883 | BP5: 17.79461 | BQ5: 18.22395 | BR5: 19.62255 | BS5: 33.16999 | BT5: 16.96364 | BU5: 21.09027 | BV5: 15.77538 | BW5: 11.0874 | BX5: 22.37858 | BY5: 22.74086 | BZ5: 18.29135 | CA5: 15.65286 | CB5: 37.8069 | CC5: 20.90929 | CD5: 15.53219 | CE5: 18.28753 | CF5: 13.19869 | CG5: 40.13678 | CH5: 38.29935 | CI5: 39.02712 | CJ5: 37.73629 | CK5: 87.81686 | CL5: 41.2278 | CM5: 43.17575 | CN5: 30.88983 | CO5: 28.34702 | CP5: 28.51303 | CQ5: 29.20011 | CR5: 33.17498 | CS5: 33.15183 | CT5: 57.57457 | CU5: 39.28547 | CV5: 26.41028 | CW5: 24.51787 | CX5: 21.14353 | CY5: 18.09188 | CZ5: 28.42391 | DA5: 37.00899 | DB5: 29.36483 | DC5: 47.95085 | DD5: 32.72959 | DE5: 30.47305 | DF5: 28.26028 | DG5: 23.6912
A6: 1 | B6: AS_MRC-5_20240313 | C6: 16 | D6: 13.18421 | E6: 20.71842 | F6: 18.32229 | G6: 20.08919 | H6: 54.86739 | I6: 26.39239 | J6: 28.84404 | K6: 35.51519 | L6: 19.72205 | M6: 14.56266 | N6: 17.61022 | O6: 25.40422 | P6: 16.57411 | Q6: 46.69546 | R6: 22.03644 | S6: 19.17792 | T6: 20.56149 | U6: 16.94226 | V6: 31.62164 | W6: 39.93895 | X6: 39.6668 | Y6: 41.41233 | Z6: 94.84538 | AA6: 42.26057 | AB6: 39.43633 | AC6: 43.45293 | AD6: 39.61641 | AE6: 15.28751 | AF6: 13.66088 | AG6: 16.96958 | AH6: 14.48611 | AI6: 50.91537 | AJ6: 20.5352 | AK6: 22.11716 | AL6: 17.30673 | AM6: 11.0424 | AN6: 27.43452 | AO6: 26.62691 | AP6: 28.86862 | AQ6: 39.87591 | AR6: 61.03645 | AS6: 42.48743 | AT6: 30.29972 | AU6: 31.73364 | AV6: 42.7705 | AW6: 28.86159 | AX6: 26.70673 | AY6: 36.21046 | AZ6: 31.29015 | BA6: 53.58611 | BB6: 30.19374 | BC6: 33.57675 | BD6: 30.78644 | BE6: 21.43104 | BF6: 41.4897 | BG6: 43.15778 | BH6: 37.37947 | BI6: 42.40808 | BJ6: 79.95519 | BK6: 46.9325 | BL6: 51.58688 | BM6: 53.74208 | BN6: 47.28119 | BO6: 18.62475 | BP6: 21.28756 | BQ6: 20.36823 | BR6: 20.75523 | BS6: 38.57968 | BT6: 20.19196 | BU6: 24.15934 | BV6: 19.04195 | BW6: 12.76893 | BX6: 22.84221 | BY6: 22.65926 | BZ6: 18.21173 | CA6: 17.99682 | CB6: 39.49239 | CC6: 22.72809 | CD6: 15.01994 | CE6: 18.89485 | CF6: 13.09236 | CG6: 42.528 | CH6: 41.40714 | CI6: 40.20364 | CJ6: 40.31134 | CK6: 90.59904 | CL6: 44.60924 | CM6: 43.66491 | CN6: 29.3735 | CO6: 31.07933 | CP6: 28.15108 | CQ6: 35.06993 | CR6: 36.7488 | CS6: 36.20322 | CT6: 65.02711 | CU6: 43.24443 | CV6: 27.47084 | CW6: 29.55665 | CX6: 22.26146 | CY6: 18.22026 | CZ6: 29.39931 | DA6: 40.33483 | DB6: 33.08198 | DC6: 49.10907 | DD6: 36.21591 | DE6: 30.77803 | DF6: 33.1114 | DG6: 24.87578
A7: 1 | B7: AS_MRC-5_20240313 | C7: 20 | D7: 15.47025 | E7: 22.95291 | F7: 21.08596 | G7: 23.22826 | H7: 61.57862 | I7: 29.72738 | J7: 32.61377 | K7: 40.57931 | L7: 23.58016 | M7: 17.20068 | N7: 17.72283 | O7: 26.53792 | P7: 17.61794 | Q7: 46.26448 | R7: 25.16336 | S7: 19.81848 | T7: 19.83651 | U7: 20.55576 | V7: 35.46854 | W7: 42.27279 | X7: 41.69942 | Y7: 49.44712 | Z7: 96.20096 | AA7: 49.4138 | AB7: 47.37946 | AC7: 51.26884 | AD7: 45.04951 | AE7: 16.24215 | AF7: 15.9136 | AG7: 13.24526 | AH7: 16.39669 | AI7: 55.48267 | AJ7: 21.1214 | AK7: 22.67373 | AL7: 18.51105 | AM7: 11.47823 | AN7: 34.04317 | AO7: 32.7819 | AP7: 36.32518 | AQ7: 44.08011 | AR7: 69.46391 | AS7: 50.42067 | AT7: 32.35884 | AU7: 38.51426 | AV7: 47.03699 | AW7: 31.65483 | AX7: 29.60972 | AY7: 40.44662 | AZ7: 36.61283 | BA7: 62.09353 | BB7: 34.14302 | BC7: 39.37042 | BD7: 36.22739 | BE7: 26.34199 | BF7: 47.10186 | BG7: 50.44054 | BH7: 42.96144 | BI7: 47.81099 | BJ7: 87.44201 | BK7: 55.63586 | BL7: 56.97525 | BM7: 60.26879 | BN7: 52.94771 | BO7: 21.47154 | BP7: 22.20519 | BQ7: 23.6871 | BR7: 26.23969 | BS7: 44.56123 | BT7: 23.67843 | BU7: 28.33227 | BV7: 21.2474 | BW7: 13.56336 | BX7: 24.81315 | BY7: 24.01565 | BZ7: 19.22237 | CA7: 19.5305 | CB7: 44.43393 | CC7: 23.34879 | CD7: 16.98194 | CE7: 21.64937 | CF7: 14.02023 | CG7: 45.18268 | CH7: 43.41195 | CI7: 43.13817 | CJ7: 45.46622 | CK7: 91.73936 | CL7: 49.95234 | CM7: 45.8117 | CN7: 36.58715 | CO7: 31.25328 | CP7: 35.69903 | CQ7: 40.27821 | CR7: 42.4929 | CS7: 40.32957 | CT7: 75.97266 | CU7: 51.24556 | CV7: 33.67059 | CW7: 36.07504 | CX7: 24.01517 | CY7: 22.72577 | CZ7: 34.75934 | DA7: 46.19578 | DB7: 36.71526 | DC7: 63.43374 | DD7: 48.07835 | DE7: 38.70916 | DF7: 38.56288 | DG7: 31.00169
A8: 1 | B8: AS_MRC-5_20240313 | C8: 24 | D8: 16.39737 | E8: 25.82386 | F8: 25.14833 | G8: 25.56053 | H8: 67.7326 | I8: 35.17565 | J8: 34.81738 | K8: 44.01722 | L8: 27.03159 | M8: 19.12772 | N8: 23.26807 | O8: 31.41799 | P8: 22.09319 | Q8: 54.19074 | R8: 28.82402 | S8: 24.48754 | T8: 25.66242 | U8: 24.61258 | V8: 41.65538 | W8: 49.38763 | X8: 49.49511 | Y8: 56.41417 | Z8: 96.58729 | AA8: 59.16199 | AB8: 55.19299 | AC8: 58.46946 | AD8: 53.07993 | AE8: 19.23432 | AF8: 19.09562 | AG8: 19.08217 | AH8: 19.24053 | AI8: 62.92607 | AJ8: 27.34395 | AK8: 24.17593 | AL8: 19.60999 | AM8: 13.12698 | AN8: 40.70421 | AO8: 37.7944 | AP8: 38.7582 | AQ8: 53.04777 | AR8: 79.18262 | AS8: 59.75135 | AT8: 39.72471 | AU8: 43.14365 | AV8: 54.74855 | AW8: 39.26935 | AX8: 37.55742 | AY8: 45.77667 | AZ8: 41.11389 | BA8: 72.31548 | BB8: 41.65708 | BC8: 46.98453 | BD8: 41.93332 | BE8: 31.56666 | BF8: 54.49812 | BG8: 59.05601 | BH8: 52.53142 | BI8: 58.14302 | BJ8: 94.10361 | BK8: 65.80939 | BL8: 67.31459 | BM8: 72.49802 | BN8: 65.57419 | BO8: 26.20036 | BP8: 27.02243 | BQ8: 25.41193 | BR8: 29.16043 | BS8: 52.9066 | BT8: 28.58139 | BU8: 33.10854 | BV8: 25.53131 | BW8: 16.37326 | BX8: 26.1171 | BY8: 26.60716 | BZ8: 22.11244 | CA8: 21.7602 | CB8: 45.70422 | CC8: 28.2988 | CD8: 19.31586 | CE8: 23.47881 | CF8: 17.2717 | CG8: 51.89514 | CH8: 53.23884 | CI8: 52.4735 | CJ8: 54.39487 | CK8: 93.88323 | CL8: 56.78472 | CM8: 51.64985 | CN8: 43.50962 | CO8: 37.43614 | CP8: 41.34424 | CQ8: 47.91302 | CR8: 50.47592 | CS8: 50.75612 | CT8: 82.6768 | CU8: 54.25555 | CV8: 40.09998 | CW8: 40.30909 | CX8: 29.80222 | CY8: 27.3083 | CZ8: 40.11378 | DA8: 55.10899 | DB8: 44.0767 | DC8: 69.36155 | DD8: 53.26055 | DE8: 43.06381 | DF8: 42.44953 | DG8: 36.12196
A9: 1 | B9: AS_MRC-5_20240313 | C9: 28 | D9: 19.6274 | E9: 27.44933 | F9: 28.99755 | G9: 28.80115 | H9: 70.92213 | I9: 41.23442 | J9: 41.41697 | K9: 51.9958 | L9: 30.95116 | M9: 21.31658 | N9: 24.08483 | O9: 32.95332 | P9: 25.83862 | Q9: 56.35823 | R9: 32.53496 | S9: 28.2488 | T9: 27.94846 | U9: 26.62682 | V9: 51.00319 | W9: 56.11335 | X9: 61.2207 | Y9: 64.78597 | Z9: 96.84598 | AA9: 66.29794 | AB9: 60.20965 | AC9: 64.73871 | AD9: 61.84932 | AE9: 21.75365 | AF9: 20.82031 | AG9: 25.85419 | AH9: 22.27696 | AI9: 68.2652 | AJ9: 30.70613 | AK9: 30.43159 | AL9: 22.601 | AM9: 15.53404 | AN9: 47.31999 | AO9: 47.1565 | AP9: 51.33939 | AQ9: 61.08105 | AR9: 85.31816 | AS9: 68.70629 | AT9: 46.14217 | AU9: 49.98375 | AV9: 66.28558 | AW9: 44.2686 | AX9: 43.52724 | AY9: 59.74609 | AZ9: 50.19565 | BA9: 79.53548 | BB9: 46.21135 | BC9: 52.2394 | BD9: 47.56358 | BE9: 37.84466 | BF9: 66.44039 | BG9: 68.3098 | BH9: 63.30187 | BI9: 70.54612 | BJ9: 96.55408 | BK9: 78.03683 | BL9: 81.80268 | BM9: 84.5701 | BN9: 75.37151 | BO9: 31.33079 | BP9: 31.69 | BQ9: 29.47935 | BR9: 36.62088 | BS9: 59.48003 | BT9: 32.61364 | BU9: 38.88549 | BV9: 29.85502 | BW9: 19.67801 | BX9: 32.83428 | BY9: 31.36268 | BZ9: 24.2365 | CA9: 23.46127 | CB9: 51.94774 | CC9: 32.17295 | CD9: 20.11876 | CE9: 25.42867 | CF9: 19.55781 | CG9: 59.04345 | CH9: 58.35056 | CI9: 53.29504 | CJ9: 60.78248 | CK9: 95.37431 | CL9: 68.87258 | CM9: 58.62613 | CN9: 49.70628 | CO9: 45.92882 | CP9: 48.68656 | CQ9: 56.69047 | CR9: 55.41159 | CS9: 55.99684 | CT9: 89.9147 | CU9: 65.19148 | CV9: 47.09272 | CW9: 50.4557 | CX9: 37.20976 | CY9: 30.22542 | CZ9: 46.41178 | DA9: 62.42372 | DB9: 53.79835 | DC9: 76.57376 | DD9: 62.9809 | DE9: 50.1531 | DF9: 52.16469 | DG9: 42.12447
A10: 1 | B10: AS_MRC-5_20240313 | C10: 32 | D10: 22.61706 | E10: 30.78009 | F10: 35.39841 | G10: 33.43517 | H10: 79.34776 | I10: 47.93357 | J10: 51.08228 | K10: 59.19103 | L10: 37.45629 | M10: 25.6099 | N10: 26.57063 | O10: 41.19175 | P10: 30.44738 | Q10: 65.55226 | R10: 40.62479 | S10: 33.21132 | T10: 35.67799 | U10: 34.22886 | V10: 60.7146 | W10: 70.39056 | X10: 67.18627 | Y10: 76.27635 | Z10: 97.38438 | AA10: 77.06552 | AB10: 71.75488 | AC10: 77.84043 | AD10: 71.56905 | AE10: 27.92757 | AF10: 26.87309 | AG10: 30.9461 | AH10: 25.80215 | AI10: 74.71686 | AJ10: 37.11449 | AK10: 34.68559 | AL10: 25.555 | AM10: 18.39905 | AN10: 60.01256 | AO10: 59.94918 | AP10: 59.05171 | AQ10: 74.69549 | AR10: 93.59347 | AS10: 78.77151 | AT10: 56.10542 | AU10: 59.32515 | AV10: 77.36662 | AW10: 53.33348 | AX10: 54.3106 | AY10: 71.30846 | AZ10: 59.29593 | BA10: 87.36232 | BB10: 57.29826 | BC10: 64.23671 | BD10: 60.87515 | BE10: 46.02075 | BF10: 78.72255 | BG10: 81.0497 | BH10: 77.15704 | BI10: 83.96566 | BJ10: 98.87339 | BK10: 85.21675 | BL10: 89.50325 | BM10: 92.55094 | BN10: 87.57689 | BO10: 39.66025 | BP10: 40.2455 | BQ10: 39.1758 | BR10: 43.41087 | BS10: 70.76902 | BT10: 42.19241 | BU10: 49.21022 | BV10: 36.82119 | BW10: 22.94375 | BX10: 36.40666 | BY10: 36.53546 | BZ10: 27.02045 | CA10: 29.57434 | CB10: 63.35028 | CC10: 39.72096 | CD10: 25.25808 | CE10: 28.37883 | CF10: 21.21257 | CG10: 75.34575 | CH10: 70.72668 | CI10: 67.69804 | CJ10: 70.93074 | CK10: 96.70126 | CL10: 75.58832 | CM10: 73.6748 | CN10: 63.34791 | CO10: 46.43213 | CP10: 59.28977 | CQ10: 68.5863 | CR10: 67.54794 | CS10: 68.3352 | CT10: 95.33053 | CU10: 78.4015 | CV10: 56.13001 | CW10: 62.12774 | CX10: 45.47373 | CY10: 38.78162 | CZ10: 57.61432 | DA10: 74.1241 | DB10: 66.96979 | DC10: 89.05362 | DD10: 72.18811 | DE10: 60.29761 | DF10: 62.47507 | DG10: 51.56707
A11: 1 | B11: AS_MRC-5_20240313 | C11: 36 | D11: 26.71288 | E11: 34.06496 | F11: 38.74842 | G11: 37.97237 | H11: 81.64725 | I11: 52.89943 | J11: 57.34859 | K11: 66.31057 | L11: 44.37063 | M11: 28.83174 | N11: 31.58489 | O11: 46.37114 | P11: 33.08887 | Q11: 74.92494 | R11: 45.65286 | S11: 38.80586 | T11: 39.37466 | U11: 36.89487 | V11: 66.93523 | W11: 75.06406 | X11: 75.79025 | Y11: 84.476 | Z11: 98.08313 | AA11: 83.16952 | AB11: 81.12304 | AC11: 86.54385 | AD11: 79.77518 | AE11: 30.897 | AF11: 29.49061 | AG11: 33.83044 | AH11: 29.27797 | AI11: 79.62386 | AJ11: 43.74405 | AK11: 41.05885 | AL11: 30.50562 | AM11: 19.96339 | AN11: 68.08839 | AO11: 69.08817 | AP11: 70.06037 | AQ11: 83.88077 | AR11: 96.51988 | AS11: 87.38882 | AT11: 64.67227 | AU11: 69.37487 | AV11: 85.19887 | AW11: 60.20958 | AX11: 63.32386 | AY11: 78.56432 | AZ11: 67.6917 | BA11: 91.55868 | BB11: 71.43029 | BC11: 74.51405 | BD11: 70.80248 | BE11: 53.91089 | BF11: 90.56954 | BG11: 90.02458 | BH11: 87.24281 | BI11: 91.58278 | BJ11: 99.63157 | BK11: 93.2219 | BL11: 95.18431 | BM11: 97.00031 | BN11: 91.97395 | BO11: 48.52191 | BP11: 50.14129 | BQ11: 43.94879 | BR11: 54.97855 | BS11: 81.03188 | BT11: 51.25996 | BU11: 56.79169 | BV11: 45.4805 | BW11: 28.99919 | BX11: 41.4856 | BY11: 43.72527 | BZ11: 33.53167 | CA11: 33.02509 | CB11: 70.23328 | CC11: 44.94285 | CD11: 30.32616 | CE11: 33.16467 | CF11: 26.09007 | CG11: 77.88496 | CH11: 74.46869 | CI11: 75.09397 | CJ11: 78.25864 | CK11: 97.38773 | CL11: 83.34557 | CM11: 75.79668 | CN11: 73.94251 | CO11: 51.08773 | CP11: 66.99198 | CQ11: 77.10555 | CR11: 76.09655 | CS11: 77.40446 | CT11: 97.55879 | CU11: 86.80056 | CV11: 66.88708 | CW11: 69.15783 | CX11: 56.28858 | CY11: 44.38347 | CZ11: 67.17063 | DA11: 81.80172 | DB11: 76.67517 | DC11: 95.6993 | DD11: 85.92998 | DE11: 70.13753 | DF11: 71.94984 | DG11: 62.81667
A12: 1 | B12: AS_MRC-5_20240313 | C12: 40 | D12: 29.63847 | E12: 37.43744 | F12: 42.31227 | G12: 40.76007 | H12: 87.00858 | I12: 59.68613 | J12: 63.0143 | K12: 74.00452 | L12: 49.88882 | M12: 31.79441 | N12: 32.32347 | O12: 46.54863 | P12: 35.07588 | Q12: 76.75474 | R12: 51.40993 | S12: 41.8933 | T12: 43.21104 | U12: 38.98895 | V12: 76.32204 | W12: 82.19931 | X12: 82.63378 | Y12: 89.32118 | Z12: 98.23904 | AA12: 87.93678 | AB12: 86.74197 | AC12: 88.39822 | AD12: 86.80159 | AE12: 32.37933 | AF12: 32.2312 | AG12: 36.65886 | AH12: 33.97992 | AI12: 83.44228 | AJ12: 48.23919 | AK12: 45.90192 | AL12: 34.14964 | AM12: 23.21433 | AN12: 75.95279 | AO12: 75.67027 | AP12: 77.62866 | AQ12: 89.80905 | AR12: 98.2891 | AS12: 92.86803 | AT12: 73.43571 | AU12: 75.53848 | AV12: 89.60063 | AW12: 66.51688 | AX12: 71.77837 | AY12: 86.56523 | AZ12: 77.88769 | BA12: 94.74234 | BB12: 77.94102 | BC12: 80.89188 | BD12: 75.44914 | BE12: 60.46539 | BF12: 94.01435 | BG12: 95.20644 | BH12: 91.2711 | BI12: 94.32043 | BJ12: 99.82926 | BK12: 96.56775 | BL12: 96.61604 | BM12: 97.7836 | BN12: 95.51887 | BO12: 54.13803 | BP12: 56.39027 | BQ12: 51.47597 | BR12: 63.78531 | BS12: 87.1431 | BT12: 61.51934 | BU12: 68.15887 | BV12: 50.73659 | BW12: 33.02707 | BX12: 47.33003 | BY12: 43.13538 | BZ12: 32.59929 | CA12: 37.22253 | CB12: 75.21273 | CC12: 50.01202 | CD12: 31.66418 | CE12: 35.26231 | CF12: 27.76135 | CG12: 79.87653 | CH12: 80.75141 | CI12: 81.37511 | CJ12: 81.31835 | CK12: 97.70473 | CL12: 83.91109 | CM12: 78.66218 | CN12: 77.07064 | CO12: 48.81548 | CP12: 75.81116 | CQ12: 88.01601 | CR12: 82.45048 | CS12: 87.01383 | CT12: 98.79254 | CU12: 93.73914 | CV12: 74.11044 | CW12: 79.96462 | CX12: 66.73042 | CY12: 52.5224 | CZ12: 72.74024 | DA12: 87.57976 | DB12: 83.77704 | DC12: 96.90976 | DD12: 91.83469 | DE12: 75.79231 | DF12: 80.37989 | DG12: 73.81337
A13: 1 | B13: AS_MRC-5_20240313 | C13: 44 | D13: 32.3316 | E13: 40.86409 | F13: 50.69643 | G13: 47.39619 | H13: 89.95151 | I13: 65.07101 | J13: 70.04712 | K13: 77.38786 | L13: 54.0091 | M13: 31.09074 | N13: 37.60381 | O13: 53.74112 | P13: 40.42785 | Q13: 77.21379 | R13: 53.88488 | S13: 44.54948 | T13: 45.6657 | U13: 42.04907 | V13: 78.48728 | W13: 88.2385 | X13: 89.55569 | Y13: 87.9725 | Z13: 98.43026 | AA13: 89.23172 | AB13: 91.02702 | AC13: 87.80137 | AD13: 88.20605 | AE13: 38.5329 | AF13: 36.74777 | AG13: 44.93103 | AH13: 40.86517 | AI13: 87.83162 | AJ13: 56.39246 | AK13: 50.81689 | AL13: 39.53569 | AM13: 26.96603 | AN13: 85.39042 | AO13: 84.84314 | AP13: =AVERAGE(AP12,AP14) -> 87.64085 | AQ13: 91.31904 | AR13: 99.28963 | AS13: 95.60225 | AT13: 82.66225 | AU13: 83.85558 | AV13: 93.98567 | AW13: 76.59937 | AX13: 82.37823 | AY13: 92.3572 | AZ13: 84.82791 | BA13: 96.96623 | BB13: 85.45714 | BC13: 88.61853 | BD13: 86.19366 | BE13: 68.43141 | BF13: 96.35154 | BG13: 96.33317 | BH13: 95.23649 | BI13: 96.35605 | BJ13: 99.90684 | BK13: 98.47751 | BL13: 96.44627 | BM13: 99.21409 | BN13: 97.82465 | BO13: 59.32133 | BP13: 68.87169 | BQ13: 59.46418 | BR13: 72.74154 | BS13: 93.47526 | BT13: 70.15392 | BU13: 77.13996 | BV13: 58.17068 | BW13: 38.8904 | BX13: 49.10149 | BY13: 49.78747 | BZ13: 35.42969 | CA13: 39.69181 | CB13: 79.7646 | CC13: 53.20081 | CD13: 38.00999 | CE13: 42.80574 | CF13: 32.49037 | CG13: 82.84445 | CH13: 83.18086 | CI13: 80.27187 | CJ13: 80.44505 | CK13: 97.63324 | CL13: 83.23112 | CM13: 88.25878 | CN13: 86.82179 | CO13: 74.3978 | CP13: 84.49792 | CQ13: 91.42271 | CR13: 90.41179 | CS13: 92.12282 | CT13: 99.46706 | CU13: 96.47563 | CV13: 83.9229 | CW13: 88.22484 | CX13: 70.58887 | CY13: 61.80875 | CZ13: 84.1887 | DA13: 93.57176 | DB13: 91.87151 | DC13: 99.10272 | DD13: 95.91721 | DE13: 86.64191 | DF13: 87.55087 | DG13: 82.25087
A14: 1 | B14: AS_MRC-5_20240313 | C14: 48 | D14: 46.29753 | E14: 59.14616 | F14: 67.07878 | G14: 61.63925 | H14: 96.14066 | I14: 80.06241 | J14: 82.52888 | K14: 89.62952 | L14: 70.38748 | M14: 49.37437 | N14: 57.47561 | O14: 80.36638 | P14: 60.90288 | Q14: 92.69688 | R14: 76.07811 | S14: 61.60634 | T14: 69.89797 | U14: 64.4228 | V14: 93.82581 | W14: 95.86919 | X14: 94.39179 | Y14: 98.0873 | Z14: 99.75415 | AA14: 96.57875 | AB14: 97.08854 | AC14: 97.06458 | AD14: 96.56995 | AE14: 52.57867 | AF14: 52.68514 | AG14: 63.49131 | AH14: 54.9526 | AI14: 96.60278 | AJ14: 72.9908 | AK14: 69.14431 | AL14: 52.51899 | AM14: 37.60967 | AN14: 96.46961 | AO14: 96.65115 | AP14: 97.65304 | AQ14: 99.05471 | AR14: 99.87679 | AS14: 99.44171 | AT14: 95.87317 | AU14: 95.04151 | AV14: 99.03394 | AW14: 93.54716 | AX14: 95.88136 | AY14: 99.06782 | AZ14: 97.16551 | BA14: 99.51171 | BB14: 96.89507 | BC14: 96.82596 | BD14: 96.55573 | BE14: 86.61754 | BF14: 99.59531 | BG14: 99.70395 | BH14: 99.305 | BI14: 99.88445 | BJ14: 99.99343 | BK14: 99.69364 | BL14: 99.84197 | BM14: 99.89817 | BN14: 99.5645 | BO14: 83.45525 | BP14: 86.40515 | BQ14: 80.05006 | BR14: 89.90439 | BS14: 97.82568 | BT14: 88.61526 | BU14: 93.02454 | BV14: 82.57075 | BW14: 57.42037 | BX14: 70.99356 | BY14: 67.59635 | BZ14: 52.76326 | CA14: 62.91835 | CB14: 89.58288 | CC14: 71.17754 | CD14: 54.47504 | CE14: 58.6591 | CF14: 45.91209 | CG14: 94.86607 | CH14: 95.83158 | CI14: 94.95793 | CJ14: 95.76028 | CK14: 99.8223 | CL14: 96.83839 | CM14: 96.6706 | CN14: 96.03236 | CO14: 92.7989 | CP14: 96.78738 | CQ14: 99.18638 | CR14: 98.38531 | CS14: 98.94238 | CT14: 99.9576 | CU14: 99.37199 | CV14: 95.22188 | CW14: 98.05315 | CX14: 91.95988 | CY14: 81.14018 | CZ14: 95.21348 | DA14: 99.11414 | DB14: 98.29367 | DC14: 99.92898 | DD14: 99.75217 | DE14: 97.25101 | DF14: 97.77644 | DG14: 96.2291
A15: 1 | B15: AS_MRC-5_20240313 | C15: 52 | D15: 40.80782 | E15: 59.49403 | F15: 67.91664 | G15: 61.05531 | H15: 94.65273 | I15: 82.58761 | J15: 85.34056 | K15: 89.28615 | L15: 70.81533 | M15: 49.94331 | N15: 55.14423 | O15: 75.92097 | P15: 56.4516 | Q15: 87.89281 | R15: 72.7737 | S15: 58.08177 | T15: 64.67985 | U15: 58.53118 | V15: 93.09795 | W15: 94.20864 | X15: 94.36312 | Y15: 95.33791 | Z15: 99.44397 | AA15: 95.42429 | AB15: 95.47263 | AC15: 95.08146 | AD15: 95.55992 | AE15: 58.03902 | AF15: 54.11324 | AG15: 64.35957 | AH15: 58.35281 | AI15: 95.96529 | AJ15: 78.65473 | AK15: 71.64656 | AL15: 56.43042 | AM15: 39.96073 | AN15: 97.34538 | AO15: 95.95484 | AP15: 95.44901 | AQ15: 98.81508 | AR15: 99.65028 | AS15: 98.88275 | AT15: 96.15098 | AU15: 95.496 | AV15: 98.40588 | AW15: 94.96414 | AX15: 97.22588 | AY15: 98.01587 | AZ15: 97.29697 | BA15: 99.08749 | BB15: 95.19879 | BC15: 95.84502 | BD15: 97.40999 | BE15: 89.21396 | BF15: 99.35184 | BG15: 99.49218 | BH15: 99.08735 | BI15: 99.58698 | BJ15: 99.99091 | BK15: 99.66106 | BL15: 99.65697 | BM15: 99.85317 | BN15: 99.33341 | BO15: 85.81102 | BP15: 89.00343 | BQ15: 86.30599 | BR15: 92.07153 | BS15: 98.00768 | BT15: 90.44054 | BU15: 93.94223 | BV15: 84.60474 | BW15: 63.56807 | BX15: 70.33934 | BY15: 66.47706 | BZ15: 52.21189 | CA15: 59.6468 | CB15: 87.65748 | CC15: 67.22766 | CD15: 52.67496 | CE15: 51.57048 | CF15: 44.83398 | CG15: 91.4098 | CH15: 93.6208 | CI15: 90.23779 | CJ15: 92.87703 | CK15: 98.54779 | CL15: 93.51951 | CM15: 92.48504 | CN15: 94.40613 | CO15: 89.43407 | CP15: 97.74606 | CQ15: 99.08776 | CR15: 99.04542 | CS15: 99.29025 | CT15: 99.90453 | CU15: 98.99728 | CV15: 96.11485 | CW15: 98.3602 | CX15: 94.69582 | CY15: 85.68816 | CZ15: 96.80226 | DA15: 98.96005 | DB15: 98.36401 | DC15: 99.92542 | DD15: 99.61054 | DE15: 97.77036 | DF15: 98.1168 | DG15: 96.42687
A16: 1 | B16: AS_MRC-5_20240313 | C16: 56 | D16: 44.53494 | E16: 63.64299 | F16: 71.40399 | G16: 64.58601 | H16: 94.80933 | I16: 84.22394 | J16: 85.66365 | K16: 89.86758 | L16: 73.66995 | M16: 48.32359 | N16: 55.28313 | O16: 77.16797 | P16: 61.92867 | Q16: 87.23052 | R16: 71.74763 | S16: 59.11884 | T16: 68.81057 | U16: 62.307 | V16: 90.55801 | W16: 92.92512 | X16: 92.69408 | Y16: 95.0676 | Z16: 99.28178 | AA16: 94.24407 | AB16: 97.40282 | AC16: 94.87952 | AD16: 95.72347 | AE16: 60.84824 | AF16: 57.99299 | AG16: 69.50427 | AH16: 61.93359 | AI16: 96.5653 | AJ16: 80.67301 | AK16: 77.35925 | AL16: 58.32461 | AM16: 45.23082 | AN16: 97.84726 | AO16: 97.72919 | AP16: 97.7048 | AQ16: 98.65876 | AR16: 99.66612 | AS16: 99.02275 | AT16: 97.1653 | AU16: 96.27704 | AV16: 98.53713 | AW16: 96.25308 | AX16: 98.59634 | AY16: 98.66442 | AZ16: 98.17526 | BA16: 99.08006 | BB16: 97.20744 | BC16: 98.08689 | BD16: 98.48147 | BE16: 91.95326 | BF16: 99.27993 | BG16: 99.60725 | BH16: 99.32514 | BI16: 99.55003 | BJ16: 99.96577 | BK16: 99.67089 | BL16: 99.61627 | BM16: 99.6011 | BN16: 99.19607 | BO16: 90.58163 | BP16: 93.67931 | BQ16: 89.74678 | BR16: 94.65894 | BS16: 98.58365 | BT16: 93.50074 | BU16: 96.75617 | BV16: 89.66271 | BW16: 71.46313 | BX16: 74.73967 | BY16: 70.01126 | BZ16: 55.45325 | CA16: 60.28094 | CB16: 87.80006 | CC16: 73.7207 | CD16: 56.59992 | CE16: 58.93213 | CF16: 50.10231 | CG16: 92.04996 | CH16: 92.99053 | CI16: 91.29391 | CJ16: 94.64598 | CK16: 98.25496 | CL16: 94.75927 | CM16: 93.93329 | CN16: 92.4668 | CO16: 90.34281 | CP16: 98.24709 | CQ16: 99.48051 | CR16: 98.36279 | CS16: 99.45558 | CT16: 99.92235 | CU16: 99.42628 | CV16: 97.38924 | CW16: 99.008 | CX16: 96.63243 | CY16: 90.13999 | CZ16: 98.28036 | DA16: 98.6802 | DB16: 98.93547 | DC16: 99.94585 | DD16: 99.80577 | DE16: 98.33151 | DF16: 98.22613 | DG16: 97.70938
A17: 1 | B17: AS_MRC-5_20240313 | C17: 60 | D17: 48.35589 | E17: 67.30038 | F17: 73.56329 | G17: 63.86083 | H17: 94.45968 | I17: 87.23394 | J17: 87.01205 | K17: 90.30901 | L17: 76.01794 | M17: 53.21439 | N17: 55.38038 | O17: 76.84747 | P17: 58.89724 | Q17: 90.07594 | R17: 74.37453 | S17: 64.89059 | T17: 67.99771 | U17: 65.45993 | V17: 92.61097 | W17: 91.64751 | X17: 93.87662 | Y17: 95.68933 | Z17: 98.63246 | AA17: 95.23792 | AB17: 96.69867 | AC17: 94.54545 | AD17: 95.40305 | AE17: 65.37253 | AF17: 67.75861 | AG17: 76.89849 | AH17: 72.18237 | AI17: 96.66698 | AJ17: 84.4043 | AK17: 81.40508 | AL17: 67.87648 | AM17: 51.96596 | AN17: 97.55032 | AO17: 98.22101 | AP17: 97.69565 | AQ17: 99.07841 | AR17: 99.40757 | AS17: 99.00711 | AT17: 97.72836 | AU17: 98.23617 | AV17: 98.44643 | AW17: 96.45678 | AX17: 98.46011 | AY17: 98.05514 | AZ17: 98.9322 | BA17: 99.48118 | BB17: 97.69708 | BC17: 98.26943 | BD17: 99.00752 | BE17: 95.3788 | BF17: 99.36749 | BG17: 99.73066 | BH17: 99.23521 | BI17: 99.50188 | BJ17: 99.94926 | BK17: 99.55453 | BL17: 99.60384 | BM17: 99.75954 | BN17: 99.25242 | BO17: 94.28465 | BP17: 95.20165 | BQ17: 94.40955 | BR17: 96.52159 | BS17: 98.77629 | BT17: 95.17522 | BU17: 97.61445 | BV17: 92.3081 | BW17: 77.95625 | BX17: 77.19412 | BY17: 73.55373 | BZ17: 60.52925 | CA17: 68.98703 | CB17: 89.03463 | CC17: 75.15762 | CD17: 56.74354 | CE17: 60.09055 | CF17: 53.4209 | CG17: 91.62498 | CH17: 91.49687 | CI17: 93.39946 | CJ17: 93.19717 | CK17: 98.06681 | CL17: 96.37804 | CM17: 94.50667 | CN17: 93.07767 | CO17: 91.19679 | CP17: 99.19294 | CQ17: 99.51997 | CR17: 99.15695 | CS17: 99.39971 | CT17: 99.90459 | CU17: 98.83625 | CV17: 97.99689 | CW17: 99.21929 | CX17: 98.29095 | CY17: 91.38719 | CZ17: 98.40868 | DA17: 99.14629 | DB17: 99.01845 | DC17: 99.91457 | DD17: 99.8316 | DE17: 98.60358 | DF17: 98.61007 | DG17: 97.72413
A18: 1 | B18: AS_MRC-5_20240313 | C18: 64 | D18: 52.18668 | E18: 71.47823 | F18: 80.35333 | G18: 73.7991 | H18: 95.69821 | I18: 89.54163 | J18: 90.20187 | K18: 90.86026 | L18: 79.94946 | M18: 56.96247 | N18: 60.82801 | O18: 78.36163 | P18: 69.11774 | Q18: 87.63329 | R18: 77.66191 | S18: 66.20697 | T18: 69.58069 | U18: 67.64217 | V18: 93.46638 | W18: 93.65104 | X18: 91.12865 | Y18: 95.07935 | Z18: 99.18855 | AA18: 96.04177 | AB18: 97.4089 | AC18: 96.01118 | AD18: 96.6452 | AE18: 72.83818 | AF18: 73.04093 | AG18: 82.8222 | AH18: 78.13074 | AI18: 97.12958 | AJ18: 92.34627 | AK18: 87.00372 | AL18: 73.79664 | AM18: 62.51523 | AN18: 98.5133 | AO18: 98.63717 | AP18: 96.67579 | AQ18: 99.22087 | AR18: 99.60588 | AS18: 99.32535 | AT18: 97.79372 | AU18: 97.35966 | AV18: 99.17087 | AW18: 97.23229 | AX18: 98.73722 | AY18: 99.11973 | AZ18: 99.01845 | BA18: 99.32671 | BB18: 98.06196 | BC18: 97.82459 | BD18: 99.34836 | BE18: 96.77332 | BF18: 99.41174 | BG18: 99.43243 | BH18: 99.48392 | BI18: 99.46131 | BJ18: 99.92775 | BK18: 99.59448 | BL18: 98.78223 | BM18: 99.54285 | BN18: 99.69447 | BO18: 95.29324 | BP18: 97.41272 | BQ18: 96.68385 | BR18: 97.14133 | BS18: 99.04863 | BT18: 97.57668 | BU18: 97.80805 | BV18: 95.58996 | BW18: 84.67493 | BX18: 78.41284 | BY18: 75.99992 | BZ18: 65.54243 | CA18: 73.09119 | CB18: 89.59223 | CC18: 82.48415 | CD18: 57.93413 | CE18: 65.69684 | CF18: 61.20199 | CG18: 93.20223 | CH18: 92.41586 | CI18: 94.73524 | CJ18: 92.55962 | CK18: 98.84478 | CL18: 91.68822 | CM18: 94.39917 | CN18: 95.02499 | CO18: 90.21689 | CP18: 99.16063 | CQ18: 99.26341 | CR18: 99.20789 | CS18: 99.30704 | CT18: 99.9582 | CU18: 99.30048 | CV18: 98.33205 | CW18: 99.6543 | CX18: 98.56731 | CY18: 92.27074 | CZ18: 99.22032 | DA18: 99.37193 | DB18: 98.84697 | DC18: 99.8014 | DD18: 99.76193 | DE18: 98.68034 | DF18: 99.23015 | DG18: 98.48141
A19: 1 | B19: AS_MRC-5_20240313 | C19: 68 | D19: 57.08294 | E19: 75.95238 | F19: 80.09472 | G19: 73.92754 | H19: 94.63663 | I19: 91.47406 | J19: 90.97027 | K19: 93.19506 | L19: 80.66801 | M19: 52.31254 | N19: 62.83092 | O19: 82.4031 | P19: 68.25543 | Q19: 86.62778 | R19: 80.38769 | S19: 71.41991 | T19: 68.71149 | U19: 70.0788 | V19: 92.4681 | W19: 94.9959 | X19: 94.34147 | Y19: 96.41096 | Z19: 99.38244 | AA19: 95.57091 | AB19: 96.35366 | AC19: 95.24038 | AD19: 96.95346 | AE19: 79.44875 | AF19: 77.48435 | AG19: 88.13654 | AH19: 86.25922 | AI19: 97.44966 | AJ19: 92.10937 | AK19: 89.12164 | AL19: 80.1245 | AM19: 68.56172 | AN19: 97.88884 | AO19: 98.53236 | AP19: 97.14625 | AQ19: 98.98048 | AR19: 99.63416 | AS19: 99.3278 | AT19: 97.66704 | AU19: 98.68443 | AV19: 99.29755 | AW19: 97.89471 | AX19: 98.88288 | AY19: 98.79943 | AZ19: 99.09063 | BA19: 99.57713 | BB19: 98.60836 | BC19: 98.47137 | BD19: 99.33587 | BE19: 97.83777 | BF19: 98.89292 | BG19: 99.57713 | BH19: 98.78517 | BI19: 99.25194 | BJ19: 99.95233 | BK19: 99.31988 | BL19: 99.60445 | BM19: 99.47559 | BN19: 99.30588 | BO19: 96.36712 | BP19: 98.16529 | BQ19: 97.90073 | BR19: 97.05146 | BS19: 98.86561 | BT19: 98.13898 | BU19: 98.33143 | BV19: 94.20468 | BW19: 90.19415 | BX19: 82.77732 | BY19: 79.6905 | BZ19: 65.96194 | CA19: 71.30804 | CB19: 91.74012 | CC19: 83.59094 | CD19: 61.24973 | CE19: 68.13899 | CF19: 62.67558 | CG19: 92.43396 | CH19: 93.79057 | CI19: 94.84715 | CJ19: 94.25623 | CK19: 98.84021 | CL19: 93.16571 | CM19: 94.90945 | CN19: 93.03362 | CO19: 89.79341 | CP19: 98.92823 | CQ19: 99.36488 | CR19: 99.48992 | CS19: 99.45646 | CT19: 99.94392 | CU19: 98.9128 | CV19: 98.58438 | CW19: 99.60376 | CX19: 98.85899 | CY19: 94.98743 | CZ19: 98.70145 | DA19: 99.46842 | DB19: 99.06448 | DC19: 99.81567 | DD19: 99.77026 | DE19: 98.97514 | DF19: 98.81071 | DG19: 98.12712
A20: 1 | B20: AS_MRC-5_20240313 | C20: 72 | D20: 78.39454 | E20: 91.92068 | F20: 92.08575 | G20: 88.78626 | H20: 99.19839 | I20: 98.05049 | J20: 97.34962 | K20: 98.366 | L20: 94.61919 | M20: 86.37429 | N20: 91.08384 | O20: 96.69894 | P20: 91.94069 | Q20: 98.31662 | R20: 96.51551 | S20: 93.45641 | T20: 94.41522 | U20: 92.57218 | V20: 98.41386 | W20: 99.31155 | X20: 98.50804 | Y20: 99.51028 | Z20: 99.9754 | AA20: 99.52995 | AB20: 99.63306 | AC20: 99.27222 | AD20: 99.59803 | AE20: 94.53391 | AF20: 94.96312 | AG20: 95.90015 | AH20: 96.18601 | AI20: 99.77259 | AJ20: 98.59859 | AK20: 98.4493 | AL20: 95.31686 | AM20: 87.17077 | AN20: 99.92215 | AO20: 99.92275 | AP20: 99.73783 | AQ20: 99.86171 | AR20: 99.97992 | AS20: 99.93874 | AT20: 99.88179 | AU20: 99.77245 | AV20: 99.9834 | AW20: 99.78331 | AX20: 99.93902 | AY20: 99.95711 | AZ20: 99.91054 | BA20: 99.95609 | BB20: 99.88969 | BC20: 99.85617 | BD20: 99.90221 | BE20: 99.83636 | BF20: 99.99296 | BG20: 99.92461 | BH20: 99.92719 | BI20: 99.989 | BJ20: 100 | BK20: 99.94672 | BL20: 99.98093 | BM20: 99.9789 | BN20: 99.98701 | BO20: 99.66025 | BP20: 99.92406 | BQ20: 99.90016 | BR20: 99.80086 | BS20: 99.97569 | BT20: 99.67288 | BU20: 99.83329 | BV20: 99.71782 | BW20: 98.41912 | BX20: 97.34859 | BY20: 95.26093 | BZ20: 90.05299 | CA20: 94.13181 | CB20: 99.05656 | CC20: 96.9769 | CD20: 87.9727 | CE20: 91.54173 | CF20: 89.6989 | CG20: 99.32351 | CH20: 99.29456 | CI20: 99.38203 | CJ20: 99.49996 | CK20: 99.98859 | CL20: 99.4394 | CM20: 99.63504 | CN20: 99.41706 | CO20: 99.11658 | CP20: 99.97977 | CQ20: 99.99357 | CR20: 99.99009 | CS20: 99.96886 | CT20: 99.99323 | CU20: 99.98367 | CV20: 99.92494 | CW20: 99.99767 | CX20: 99.95922 | CY20: 99.72102 | CZ20: 99.98804 | DA20: 99.96162 | DB20: 99.97849 | DC20: 99.99323 | DD20: 100 | DE20: 99.98517 | DF20: 99.99857 | DG20: 99.92713
C21: slope | D21: =SLOPE(D2:D20,$C2:$C20) -> 0.77365045 | E21: =SLOPE(E2:E20,$C2:$C20) -> 0.9958836 | F21: =SLOPE(F2:F20,$C2:$C20) -> 1.1153659 | G21: =SLOPE(G2:G20,$C2:$C20) -> 0.97702199 | H21: =SLOPE(H2:H20,$C2:$C20) -> 0.82204667 | I21: =SLOPE(I2:I20,$C2:$C20) -> 1.2380098 | J21: =SLOPE(J2:J20,$C2:$C20) -> 1.1708608 | K21: =SLOPE(K2:K20,$C2:$C20) -> 1.1108568 | L21: =SLOPE(L2:L20,$C2:$C20) -> 1.1559241
C22: z.test | D22: =_xlfn.Z.TEST($D21:$L21,D21) -> 2.9739684e-07 | E22: =_xlfn.Z.TEST($D21:$L21,E21) -> 0.2043081 | F22: =_xlfn.Z.TEST($D21:$L21,F21) -> 0.92128955 | G22: =_xlfn.Z.TEST($D21:$L21,G21) -> 0.1190079 | H22: =_xlfn.Z.TEST($D21:$L21,H21) -> 2.1987514e-05 | I22: =_xlfn.Z.TEST($D21:$L21,I21) -> 0.99989767 | J22: =_xlfn.Z.TEST($D21:$L21,J21) -> 0.99294113 | K22: =_xlfn.Z.TEST($D21:$L21,K21) -> 0.90811893 | L22: =_xlfn.Z.TEST($D21:$L21,L21) -> 0.98515533
C23: mean | D23: =AVERAGE($D21:$L21) -> 1.0399578
C24: stdev | D24: =STDEV($D21:$L21) -> 0.16001163
C25: z.score | D25: =STANDARDIZE(D21,AVERAGE($D21:$L21),STDEV($D21:$L21)) -> -1.6643 | E25: =STANDARDIZE(E21,AVERAGE($D21:$L21),STDEV($D21:$L21)) -> -0.27544375 | F25: =STANDARDIZE(F21,AVERAGE($D21:$L21),STDEV($D21:$L21)) -> 0.47126637 | G25: =STANDARDIZE(G21,AVERAGE($D21:$L21),STDEV($D21:$L21)) -> -0.39332027 | H25: =STANDARDIZE(H21,AVERAGE($D21:$L21),STDEV($D21:$L21)) -> -1.3618456 | I25: =STANDARDIZE(I21,AVERAGE($D21:$L21),STDEV($D21:$L21)) -> 1.2377352 | J25: =STANDARDIZE(J21,AVERAGE($D21:$L21),STDEV($D21:$L21)) -> 0.81808455 | K25: =STANDARDIZE(K21,AVERAGE($D21:$L21),STDEV($D21:$L21)) -> 0.44308672 | L25: =STANDARDIZE(L21,AVERAGE($D21:$L21),STDEV($D21:$L21)) -> 0.72473676
C26: sem | D26: =D24/SQRT(9) -> 0.05333721
C27: 95 ci | D27: =D23+(1.96*D26) -> 1.1444987
C28: q3 | D28: =_xlfn.QUARTILE.EXC($D21:$L21,3) -> 1.1633925
C29: q1 | D29: =_xlfn.QUARTILE.EXC($D21:$L21,1) -> 0.89953433
C30: 1.5*iqr | D30: =1.5*(D28-D29) -> 0.39578723
C31: min | D31: =D30-D29 -> -0.5037471
C32: max | D32: =D28+D30 -> 1.5591797

Sheet raw
A1: Vessel Name: AS_MRC-5_20240313
A2: Metric: Cells Confluence (%)
A3: Cell Type:
A4: Passage: 0
A5: Notes:
A6: Analysis: AS_Confluence_MRC-5_New_Mar31
A8: Date Time | B8: Elapsed | C8: P17 (A1), Image 1 | D8: P17 (A1), Image 2 | E8: P17 (A1), Image 3 | F8: P17 (A1), Image 4 | G8: P17 (A1), Image 5 | H8: P17 (A1), Image 6 | I8: P17 (A1), Image 7 | J8: P17 (A1), Image 8 | K8: P17 (A1), Image 9 | L8: P17 (B1), Image 1 | M8: P17 (B1), Image 2 | N8: P17 (B1), Image 3 | O8: P17 (B1), Image 4 | P8: P17 (B1), Image 5 | Q8: P17 (B1), Image 6 | R8: P17 (B1), Image 7 | S8: P17 (B1), Image 8 | T8: P17 (B1), Image 9 | U8: P14 (A2), Image 1 | V8: P14 (A2), Image 2 | W8: P14 (A2), Image 3 | X8: P14 (A2), Image 4 | Y8: P14 (A2), Image 5 | Z8: P14 (A2), Image 6 | AA8: P14 (A2), Image 7 | AB8: P14 (A2), Image 8 | AC8: P14 (A2), Image 9 | AD8: P14 (B2), Image 1 | AE8: P14 (B2), Image 2 | AF8: P14 (B2), Image 3 | AG8: P14 (B2), Image 4 | AH8: P14 (B2), Image 5 | AI8: P14 (B2), Image 6 | AJ8: P14 (B2), Image 7 | AK8: P14 (B2), Image 8 | AL8: P14 (B2), Image 9 | AM8: P12 (A3), Image 1 | AN8: P12 (A3), Image 2 | AO8: P12 (A3), Image 3 | AP8: P12 (A3), Image 4 | AQ8: P12 (A3), Image 5 | AR8: P12 (A3), Image 6 | AS8: P12 (A3), Image 7 | AT8: P12 (A3), Image 8 | AU8: P12 (A3), Image 9 | AV8: P12 (B3), Image 1 | AW8: P12 (B3), Image 2 | AX8: P12 (B3), Image 3 | AY8: P12 (B3), Image 4 | AZ8: P12 (B3), Image 5 | BA8: P12 (B3), Image 6 | BB8: P12 (B3), Image 7 | BC8: P12 (B3), Image 8 | BD8: P12 (B3), Image 9 | BE8: P9 (A4), Image 1 | BF8: P9 (A4), Image 2 | BG8: P9 (A4), Image 3 | BH8: P9 (A4), Image 4 | BI8: P9 (A4), Image 5 | BJ8: P9 (A4), Image 6 | BK8: P9 (A4), Image 7 | BL8: P9 (A4), Image 8 | BM8: P9 (A4), Image 9 | BN8: P9 (B4), Image 1 | BO8: P9 (B4), Image 2 | BP8: P9 (B4), Image 3 | BQ8: P9 (B4), Image 4 | BR8: P9 (B4), Image 5 | BS8: P9 (B4), Image 6 | BT8: P9 (B4), Image 7 | BU8: P9 (B4), Image 8 | BV8: P9 (B4), Image 9 | BW8: C1, Image 1 | BX8: C1, Image 2 | BY8: C1, Image 3 | BZ8: C1, Image 4 | CA8: C1, Image 5 | CB8: C1, Image 6 | CC8: C1, Image 7 | CD8: C1, Image 8 | CE8: C1, Image 9 | CF8: C2, Image 1 | CG8: C2, Image 2 | CH8: C2, Image 3 | CI8: C2, Image 4 | CJ8: C2, Image 5 | CK8: C2, Image 6 | CL8: C2, Image 7 | CM8: C2, Image 8 | CN8: C2, Image 9 | CO8: P6 (C3), Image 1 | CP8: P6 (C3), Image 2 | CQ8: P6 (C3), Image 3 | CR8: P6 (C3), Image 4 | CS8: P6 (C3), Image 5 | CT8: P6 (C3), Image 6 | CU8: P6 (C3), Image 7 | CV8: P6 (C3), Image 8 | CW8: P6 (C3), Image 9 | CX8: P6 (C4), Image 1 | CY8: P6 (C4), Image 2 | CZ8: P6 (C4), Image 3 | DA8: P6 (C4), Image 4 | DB8: P6 (C4), Image 5 | DC8: P6 (C4), Image 6 | DD8: P6 (C4), Image 7 | DE8: P6 (C4), Image 8 | DF8: P6 (C4), Image 9
A9: 45364.693 | B9: 0 | C9: 15.90103 | D9: 19.93151 | E9: 20.28545 | F9: 20.81676 | G9: 47.85163 | H9: 21.15876 | I9: 26.94555 | J9: 30.41998 | K9: 17.48163 | L9: 20.07027 | M9: 20.81615 | N9: 26.13814 | O9: 22.39961 | P9: 50.69296 | Q9: 19.77294 | R9: 23.76619 | S9: 24.17804 | T9: 17.18272 | U9: 23.49814 | V9: 26.78881 | W9: 27.14475 | X9: 29.04877 | Y9: 73.49908 | Z9: 25.32117 | AA9: 22.79228 | AB9: 29.01407 | AC9: 25.15666 | AD9: 12.60817 | AE9: 11.77113 | AF9: 15.2356 | AG9: 14.96182 | AH9: 38.46038 | AI9: 18.08505 | AJ9: 18.65507 | AK9: 14.74008 | AL9: 8.990863 | AM9: 17.66772 | AN9: 18.49432 | AO9: 21.86967 | AP9: 26.64261 | AQ9: 39.86868 | AR9: 28.02461 | AS9: 23.29259 | AT9: 24.98791 | AU9: 30.37547 | AV9: 22.45848 | AW9: 21.50698 | AX9: 23.03287 | AY9: 19.9692 | AZ9: 29.57639 | BA9: 17.9189 | BB9: 21.10618 | BC9: 18.7149 | BD9: 14.79553 | BE9: 22.84739 | BF9: 26.55055 | BG9: 22.74919 | BH9: 26.70516 | BI9: 48.28726 | BJ9: 28.0171 | BK9: 28.34496 | BL9: 28.61546 | BM9: 28.15812 | BN9: 11.77188 | BO9: 12.69798 | BP9: 13.96368 | BQ9: 15.91981 | BR9: 25.96393 | BS9: 12.34211 | BT9: 16.21449 | BU9: 13.91212 | BV9: 8.73511 | BW9: 23.25844 | BX9: 23.44248 | BY9: 21.90641 | BZ9: 14.89121 | CA9: 42.45267 | CB9: 22.45431 | CC9: 17.699 | CD9: 25.67874 | CE9: 16.62499 | CF9: 30.9429 | CG9: 26.47884 | CH9: 27.42522 | CI9: 30.40127 | CJ9: 70.09848 | CK9: 29.15619 | CL9: 35.37184 | CM9: 27.48347 | CN9: 22.27334 | CO9: 24.56485 | CP9: 26.32034 | CQ9: 28.64476 | CR9: 29.66257 | CS9: 44.71242 | CT9: 28.83201 | CU9: 24.74206 | CV9: 21.56564 | CW9: 17.59704 | CX9: 17.47712 | CY9: 24.4215 | CZ9: 33.82525 | DA9: 26.85103 | DB9: 35.8242 | DC9: 23.74823 | DD9: 26.88886 | DE9: 25.71194 | DF9: 20.37663
A10: 45364.86 | B10: 4 | C10: 13.70022 | D10: 17.71607 | E10: 17.29635 | F10: 18.0421 | G10: 49.06632 | H10: 21.10447 | I10: 25.14034 | J10: 30.41958 | K10: 16.75494 | L10: 13.8859 | M10: 16.50131 | N10: 23.56493 | O10: 16.36719 | P10: 47.0529 | Q10: 19.50612 | R10: 19.66264 | S10: 19.62071 | T10: 15.06173 | U10: 26.04649 | V10: 34.12355 | W10: 32.87054 | X10: 33.62585 | Y10: 88.87537 | Z10: 31.9327 | AA10: 30.24045 | AB10: 36.37989 | AC10: 32.00196 | AD10: 11.09976 | AE10: 10.27009 | AF10: 14.12894 | AG10: 12.36232 | AH10: 40.11514 | AI10: 16.26912 | AJ10: 17.13853 | AK10: 13.66013 | AL10: 8.406221 | AM10: 19.24333 | AN10: 19.17258 | AO10: 22.95427 | AP10: 27.71696 | AQ10: 44.26478 | AR10: 29.49635 | AS10: 22.32948 | AT10: 24.97582 | AU10: 30.44594 | AV10: 21.5821 | AW10: 21.09846 | AX10: 26.48943 | AY10: 22.4636 | AZ10: 36.63359 | BA10: 19.31545 | BB10: 21.85437 | BC10: 20.11111 | BD10: 15.72443 | BE10: 29.81657 | BF10: 30.10803 | BG10: 25.38646 | BH10: 30.48234 | BI10: 56.89269 | BJ10: 33.86807 | BK10: 34.944 | BL10: 35.85555 | BM10: 34.74767 | BN10: 12.63877 | BO10: 13.04606 | BP10: 11.99943 | BQ10: 15.47414 | BR10: 25.28464 | BS10: 13.66914 | BT10: 17.17951 | BU10: 13.41565 | BV10: 8.704449 | BW10: 21.26106 | BX10: 20.38345 | BY10: 18.48701 | BZ10: 12.48177 | CA10: 36.65121 | CB10: 18.43593 | CC10: 13.40649 | CD10: 19.27277 | CE10: 12.53504 | CF10: 34.54189 | CG10: 33.24826 | CH10: 32.22956 | CI10: 33.55797 | CJ10: 82.52527 | CK10: 27.92484 | CL10: 40.67048 | CM10: 27.05959 | CN10: 25.38147 | CO10: 22.46742 | CP10: 24.93806 | CQ10: 26.65019 | CR10: 25.73174 | CS10: 46.9784 | CT10: 28.09843 | CU10: 22.16114 | CV10: 19.36441 | CW10: 15.45249 | CX10: 14.7967 | CY10: 23.98847 | CZ10: 32.30291 | DA10: 24.50298 | DB10: 36.446 | DC10: 25.45489 | DD10: 23.20039 | DE10: 21.77953 | DF10: 18.32537
A11: 45365.026 | B11: 8 | C11: 14.63772 | D11: 18.37515 | E11: 17.04634 | F11: 19.79151 | G11: 48.51118 | H11: 20.22099 | I11: 26.844 | J11: 31.50288 | K11: 17.63324 | L11: 15.98646 | M11: 14.54928 | N11: 22.41737 | O11: 16.99205 | P11: 41.69014 | Q11: 20.00321 | R11: 19.56396 | S11: 19.57619 | T11: 16.01514 | U11: 26.82282 | V11: 33.68034 | W11: 34.21123 | X11: 37.13026 | Y11: 90.44067 | Z11: 33.8017 | AA11: 32.72475 | AB11: 37.61766 | AC11: 30.75694 | AD11: 12.27505 | AE11: 11.23142 | AF11: 15.05928 | AG11: 12.68425 | AH11: 45.02916 | AI11: 15.84612 | AJ11: 18.73504 | AK11: 12.68432 | AL11: 8.255984 | AM11: 22.9708 | AN11: 23.38888 | AO11: 23.03137 | AP11: 31.87221 | AQ11: 50.77913 | AR11: 31.89719 | AS11: 26.82672 | AT11: 27.56515 | AU11: 33.18618 | AV11: 23.77049 | AW11: 23.33568 | AX11: 30.28334 | AY11: 24.92344 | AZ11: 41.09676 | BA11: 22.0109 | BB11: 25.00307 | BC11: 22.42249 | BD11: 18.49172 | BE11: 30.91107 | BF11: 30.49634 | BG11: 27.43703 | BH11: 32.97735 | BI11: 63.57182 | BJ11: 35.6922 | BK11: 36.92464 | BL11: 39.12806 | BM11: 38.223 | BN11: 13.95597 | BO11: 15.79395 | BP11: 15.95 | BQ11: 15.77415 | BR11: 29.26614 | BS11: 15.11029 | BT11: 18.70622 | BU11: 13.33424 | BV11: 9.710513 | BW11: 20.90581 | BX11: 20.38639 | BY11: 19.31593 | BZ11: 14.90193 | CA11: 35.70824 | CB11: 18.18905 | CC11: 14.88363 | CD11: 19.30623 | CE11: 12.47801 | CF11: 38.17984 | CG11: 34.93826 | CH11: 31.18273 | CI11: 35.55923 | CJ11: 84.26914 | CK11: 36.14893 | CL11: 40.58013 | CM11: 28.09071 | CN11: 26.33952 | CO11: 25.70872 | CP11: 28.2303 | CQ11: 29.1803 | CR11: 28.79541 | CS11: 53.08449 | CT11: 31.73057 | CU11: 24.63512 | CV11: 22.44311 | CW11: 18.82457 | CX11: 16.54188 | CY11: 25.78643 | CZ11: 31.80896 | DA11: 26.6833 | DB11: 39.44445 | DC11: 29.67746 | DD11: 28.86678 | DE11: 23.6451 | DF11: 22.01076
A12: 45365.193 | B12: 12 | C12: 13.1321 | D12: 18.82389 | E12: 19.81971 | F12: 19.82674 | G12: 52.07235 | H12: 22.60878 | I12: 27.27046 | J12: 34.55733 | K12: 18.27551 | L12: 16.35237 | M12: 15.53281 | N12: 23.1795 | O12: 17.30305 | P12: 44.94428 | Q12: 22.29636 | R12: 20.22843 | S12: 21.27199 | T12: 18.49002 | U12: 30.22337 | V12: 38.09939 | W12: 34.83596 | X12: 37.6958 | Y12: 93.16699 | Z12: 37.58891 | AA12: 35.80153 | AB12: 42.5101 | AC12: 35.43974 | AD12: 13.90795 | AE12: 13.56329 | AF12: 17.52322 | AG12: 13.80408 | AH12: 48.97843 | AI12: 19.05547 | AJ12: 20.11588 | AK12: 17.15288 | AL12: 9.178322 | AM12: 25.65819 | AN12: 24.86977 | AO12: 29.27529 | AP12: 34.91095 | AQ12: 57.40759 | AR12: 38.10451 | AS12: 26.49223 | AT12: 27.90469 | AU12: 36.94001 | AV12: 27.41614 | AW12: 25.39199 | AX12: 30.84503 | AY12: 26.98842 | AZ12: 45.75257 | BA12: 24.75968 | BB12: 26.17338 | BC12: 26.18184 | BD12: 20.18985 | BE12: 33.89183 | BF12: 36.76286 | BG12: 32.36499 | BH12: 36.68132 | BI12: 69.7702 | BJ12: 41.09027 | BK12: 42.05351 | BL12: 44.63737 | BM12: 40.96345 | BN12: 17.17883 | BO12: 17.79461 | BP12: 18.22395 | BQ12: 19.62255 | BR12: 33.16999 | BS12: 16.96364 | BT12: 21.09027 | BU12: 15.77538 | BV12: 11.0874 | BW12: 22.37858 | BX12: 22.74086 | BY12: 18.29135 | BZ12: 15.65286 | CA12: 37.8069 | CB12: 20.90929 | CC12: 15.53219 | CD12: 18.28753 | CE12: 13.19869 | CF12: 40.13678 | CG12: 38.29935 | CH12: 39.02712 | CI12: 37.73629 | CJ12: 87.81686 | CK12: 41.2278 | CL12: 43.17575 | CM12: 30.88983 | CN12: 28.34702 | CO12: 28.51303 | CP12: 29.20011 | CQ12: 33.17498 | CR12: 33.15183 | CS12: 57.57457 | CT12: 39.28547 | CU12: 26.41028 | CV12: 24.51787 | CW12: 21.14353 | CX12: 18.09188 | CY12: 28.42391 | CZ12: 37.00899 | DA12: 29.36483 | DB12: 47.95085 | DC12: 32.72959 | DD12: 30.47305 | DE12: 28.26028 | DF12: 23.6912
A13: 45365.36 | B13: 16 | C13: 13.18421 | D13: 20.71842 | E13: 18.32229 | F13: 20.08919 | G13: 54.86739 | H13: 26.39239 | I13: 28.84404 | J13: 35.51519 | K13: 19.72205 | L13: 14.56266 | M13: 17.61022 | N13: 25.40422 | O13: 16.57411 | P13: 46.69546 | Q13: 22.03644 | R13: 19.17792 | S13: 20.56149 | T13: 16.94226 | U13: 31.62164 | V13: 39.93895 | W13: 39.6668 | X13: 41.41233 | Y13: 94.84538 | Z13: 42.26057 | AA13: 39.43633 | AB13: 43.45293 | AC13: 39.61641 | AD13: 15.28751 | AE13: 13.66088 | AF13: 16.96958 | AG13: 14.48611 | AH13: 50.91537 | AI13: 20.5352 | AJ13: 22.11716 | AK13: 17.30673 | AL13: 11.0424 | AM13: 27.43452 | AN13: 26.62691 | AO13: 28.86862 | AP13: 39.87591 | AQ13: 61.03645 | AR13: 42.48743 | AS13: 30.29972 | AT13: 31.73364 | AU13: 42.7705 | AV13: 28.86159 | AW13: 26.70673 | AX13: 36.21046 | AY13: 31.29015 | AZ13: 53.58611 | BA13: 30.19374 | BB13: 33.57675 | BC13: 30.78644 | BD13: 21.43104 | BE13: 41.4897 | BF13: 43.15778 | BG13: 37.37947 | BH13: 42.40808 | BI13: 79.95519 | BJ13: 46.9325 | BK13: 51.58688 | BL13: 53.74208 | BM13: 47.28119 | BN13: 18.62475 | BO13: 21.28756 | BP13: 20.36823 | BQ13: 20.75523 | BR13: 38.57968 | BS13: 20.19196 | BT13: 24.15934 | BU13: 19.04195 | BV13: 12.76893 | BW13: 22.84221 | BX13: 22.65926 | BY13: 18.21173 | BZ13: 17.99682 | CA13: 39.49239 | CB13: 22.72809 | CC13: 15.01994 | CD13: 18.89485 | CE13: 13.09236 | CF13: 42.528 | CG13: 41.40714 | CH13: 40.20364 | CI13: 40.31134 | CJ13: 90.59904 | CK13: 44.60924 | CL13: 43.66491 | CM13: 29.3735 | CN13: 31.07933 | CO13: 28.15108 | CP13: 35.06993 | CQ13: 36.7488 | CR13: 36.20322 | CS13: 65.02711 | CT13: 43.24443 | CU13: 27.47084 | CV13: 29.55665 | CW13: 22.26146 | CX13: 18.22026 | CY13: 29.39931 | CZ13: 40.33483 | DA13: 33.08198 | DB13: 49.10907 | DC13: 36.21591 | DD13: 30.77803 | DE13: 33.1114 | DF13: 24.87578
A14: 45365.526 | B14: 20 | C14: 15.47025 | D14: 22.95291 | E14: 21.08596 | F14: 23.22826 | G14: 61.57862 | H14: 29.72738 | I14: 32.61377 | J14: 40.57931 | K14: 23.58016 | L14: 17.20068 | M14: 17.72283 | N14: 26.53792 | O14: 17.61794 | P14: 46.26448 | Q14: 25.16336 | R14: 19.81848 | S14: 19.83651 | T14: 20.55576 | U14: 35.46854 | V14: 42.27279 | W14: 41.69942 | X14: 49.44712 | Y14: 96.20096 | Z14: 49.4138 | AA14: 47.37946 | AB14: 51.26884 | AC14: 45.04951 | AD14: 16.24215 | AE14: 15.9136 | AF14: 13.24526 | AG14: 16.39669 | AH14: 55.48267 | AI14: 21.1214 | AJ14: 22.67373 | AK14: 18.51105 | AL14: 11.47823 | AM14: 34.04317 | AN14: 32.7819 | AO14: 36.32518 | AP14: 44.08011 | AQ14: 69.46391 | AR14: 50.42067 | AS14: 32.35884 | AT14: 38.51426 | AU14: 47.03699 | AV14: 31.65483 | AW14: 29.60972 | AX14: 40.44662 | AY14: 36.61283 | AZ14: 62.09353 | BA14: 34.14302 | BB14: 39.37042 | BC14: 36.22739 | BD14: 26.34199 | BE14: 47.10186 | BF14: 50.44054 | BG14: 42.96144 | BH14: 47.81099 | BI14: 87.44201 | BJ14: 55.63586 | BK14: 56.97525 | BL14: 60.26879 | BM14: 52.94771 | BN14: 21.47154 | BO14: 22.20519 | BP14: 23.6871 | BQ14: 26.23969 | BR14: 44.56123 | BS14: 23.67843 | BT14: 28.33227 | BU14: 21.2474 | BV14: 13.56336 | BW14: 24.81315 | BX14: 24.01565 | BY14: 19.22237 | BZ14: 19.5305 | CA14: 44.43393 | CB14: 23.34879 | CC14: 16.98194 | CD14: 21.64937 | CE14: 14.02023 | CF14: 45.18268 | CG14: 43.41195 | CH14: 43.13817 | CI14: 45.46622 | CJ14: 91.73936 | CK14: 49.95234 | CL14: 45.8117 | CM14: 36.58715 | CN14: 31.25328 | CO14: 35.69903 | CP14: 40.27821 | CQ14: 42.4929 | CR14: 40.32957 | CS14: 75.97266 | CT14: 51.24556 | CU14: 33.67059 | CV14: 36.07504 | CW14: 24.01517 | CX14: 22.72577 | CY14: 34.75934 | CZ14: 46.19578 | DA14: 36.71526 | DB14: 63.43374 | DC14: 48.07835 | DD14: 38.70916 | DE14: 38.56288 | DF14: 31.00169
A15: 45365.693 | B15: 24 | C15: 16.39737 | D15: 25.82386 | E15: 25.14833 | F15: 25.56053 | G15: 67.7326 | H15: 35.17565 | I15: 34.81738 | J15: 44.01722 | K15: 27.03159 | L15: 19.12772 | M15: 23.26807 | N15: 31.41799 | O15: 22.09319 | P15: 54.19074 | Q15: 28.82402 | R15: 24.48754 | S15: 25.66242 | T15: 24.61258 | U15: 41.65538 | V15: 49.38763 | W15: 49.49511 | X15: 56.41417 | Y15: 96.58729 | Z15: 59.16199 | AA15: 55.19299 | AB15: 58.46946 | AC15: 53.07993 | AD15: 19.23432 | AE15: 19.09562 | AF15: 19.08217 | AG15: 19.24053 | AH15: 62.92607 | AI15: 27.34395 | AJ15: 24.17593 | AK15: 19.60999 | AL15: 13.12698 | AM15: 40.70421 | AN15: 37.7944 | AO15: 38.7582 | AP15: 53.04777 | AQ15: 79.18262 | AR15: 59.75135 | AS15: 39.72471 | AT15: 43.14365 | AU15: 54.74855 | AV15: 39.26935 | AW15: 37.55742 | AX15: 45.77667 | AY15: 41.11389 | AZ15: 72.31548 | BA15: 41.65708 | BB15: 46.98453 | BC15: 41.93332 | BD15: 31.56666 | BE15: 54.49812 | BF15: 59.05601 | BG15: 52.53142 | BH15: 58.14302 | BI15: 94.10361 | BJ15: 65.80939 | BK15: 67.31459 | BL15: 72.49802 | BM15: 65.57419 | BN15: 26.20036 | BO15: 27.02243 | BP15: 25.41193 | BQ15: 29.16043 | BR15: 52.9066 | BS15: 28.58139 | BT15: 33.10854 | BU15: 25.53131 | BV15: 16.37326 | BW15: 26.1171 | BX15: 26.60716 | BY15: 22.11244 | BZ15: 21.7602 | CA15: 45.70422 | CB15: 28.2988 | CC15: 19.31586 | CD15: 23.47881 | CE15: 17.2717 | CF15: 51.89514 | CG15: 53.23884 | CH15: 52.4735 | CI15: 54.39487 | CJ15: 93.88323 | CK15: 56.78472 | CL15: 51.64985 | CM15: 43.50962 | CN15: 37.43614 | CO15: 41.34424 | CP15: 47.91302 | CQ15: 50.47592 | CR15: 50.75612 | CS15: 82.6768 | CT15: 54.25555 | CU15: 40.09998 | CV15: 40.30909 | CW15: 29.80222 | CX15: 27.3083 | CY15: 40.11378 | CZ15: 55.10899 | DA15: 44.0767 | DB15: 69.36155 | DC15: 53.26055 | DD15: 43.06381 | DE15: 42.44953 | DF15: 36.12196
A16: 45365.86 | B16: 28 | C16: 19.6274 | D16: 27.44933 | E16: 28.99755 | F16: 28.80115 | G16: 70.92213 | H16: 41.23442 | I16: 41.41697 | J16: 51.9958 | K16: 30.95116 | L16: 21.31658 | M16: 24.08483 | N16: 32.95332 | O16: 25.83862 | P16: 56.35823 | Q16: 32.53496 | R16: 28.2488 | S16: 27.94846 | T16: 26.62682 | U16: 51.00319 | V16: 56.11335 | W16: 61.2207 | X16: 64.78597 | Y16: 96.84598 | Z16: 66.29794 | AA16: 60.20965 | AB16: 64.73871 | AC16: 61.84932 | AD16: 21.75365 | AE16: 20.82031 | AF16: 25.85419 | AG16: 22.27696 | AH16: 68.2652 | AI16: 30.70613 | AJ16: 30.43159 | AK16: 22.601 | AL16: 15.53404 | AM16: 47.31999 | AN16: 47.1565 | AO16: 51.33939 | AP16: 61.08105 | AQ16: 85.31816 | AR16: 68.70629 | AS16: 46.14217 | AT16: 49.98375 | AU16: 66.28558 | AV16: 44.2686 | AW16: 43.52724 | AX16: 59.74609 | AY16: 50.19565 | AZ16: 79.53548 | BA16: 46.21135 | BB16: 52.2394 | BC16: 47.56358 | BD16: 37.84466 | BE16: 66.44039 | BF16: 68.3098 | BG16: 63.30187 | BH16: 70.54612 | BI16: 96.55408 | BJ16: 78.03683 | BK16: 81.80268 | BL16: 84.5701 | BM16: 75.37151 | BN16: 31.33079 | BO16: 31.69 | BP16: 29.47935 | BQ16: 36.62088 | BR16: 59.48003 | BS16: 32.61364 | BT16: 38.88549 | BU16: 29.85502 | BV16: 19.67801 | BW16: 32.83428 | BX16: 31.36268 | BY16: 24.2365 | BZ16: 23.46127 | CA16: 51.94774 | CB16: 32.17295 | CC16: 20.11876 | CD16: 25.42867 | CE16: 19.55781 | CF16: 59.04345 | CG16: 58.35056 | CH16: 53.29504 | CI16: 60.78248 | CJ16: 95.37431 | CK16: 68.87258 | CL16: 58.62613 | CM16: 49.70628 | CN16: 45.92882 | CO16: 48.68656 | CP16: 56.69047 | CQ16: 55.41159 | CR16: 55.99684 | CS16: 89.9147 | CT16: 65.19148 | CU16: 47.09272 | CV16: 50.4557 | CW16: 37.20976 | CX16: 30.22542 | CY16: 46.41178 | CZ16: 62.42372 | DA16: 53.79835 | DB16: 76.57376 | DC16: 62.9809 | DD16: 50.1531 | DE16: 52.16469 | DF16: 42.12447
A17: 45366.026 | B17: 32 | C17: 22.61706 | D17: 30.78009 | E17: 35.39841 | F17: 33.43517 | G17: 79.34776 | H17: 47.93357 | I17: 51.08228 | J17: 59.19103 | K17: 37.45629 | L17: 25.6099 | M17: 26.57063 | N17: 41.19175 | O17: 30.44738 | P17: 65.55226 | Q17: 40.62479 | R17: 33.21132 | S17: 35.67799 | T17: 34.22886 | U17: 60.7146 | V17: 70.39056 | W17: 67.18627 | X17: 76.27635 | Y17: 97.38438 | Z17: 77.06552 | AA17: 71.75488 | AB17: 77.84043 | AC17: 71.56905 | AD17: 27.92757 | AE17: 26.87309 | AF17: 30.9461 | AG17: 25.80215 | AH17: 74.71686 | AI17: 37.11449 | AJ17: 34.68559 | AK17: 25.555 | AL17: 18.39905 | AM17: 60.01256 | AN17: 59.94918 | AO17: 59.05171 | AP17: 74.69549 | AQ17: 93.59347 | AR17: 78.77151 | AS17: 56.10542 | AT17: 59.32515 | AU17: 77.36662 | AV17: 53.33348 | AW17: 54.3106 | AX17: 71.30846 | AY17: 59.29593 | AZ17: 87.36232 | BA17: 57.29826 | BB17: 64.23671 | BC17: 60.87515 | BD17: 46.02075 | BE17: 78.72255 | BF17: 81.0497 | BG17: 77.15704 | BH17: 83.96566 | BI17: 98.87339 | BJ17: 85.21675 | BK17: 89.50325 | BL17: 92.55094 | BM17: 87.57689 | BN17: 39.66025 | BO17: 40.2455 | BP17: 39.1758 | BQ17: 43.41087 | BR17: 70.76902 | BS17: 42.19241 | BT17: 49.21022 | BU17: 36.82119 | BV17: 22.94375 | BW17: 36.40666 | BX17: 36.53546 | BY17: 27.02045 | BZ17: 29.57434 | CA17: 63.35028 | CB17: 39.72096 | CC17: 25.25808 | CD17: 28.37883 | CE17: 21.21257 | CF17: 75.34575 | CG17: 70.72668 | CH17: 67.69804 | CI17: 70.93074 | CJ17: 96.70126 | CK17: 75.58832 | CL17: 73.6748 | CM17: 63.34791 | CN17: 46.43213 | CO17: 59.28977 | CP17: 68.5863 | CQ17: 67.54794 | CR17: 68.3352 | CS17: 95.33053 | CT17: 78.4015 | CU17: 56.13001 | CV17: 62.12774 | CW17: 45.47373 | CX17: 38.78162 | CY17: 57.61432 | CZ17: 74.1241 | DA17: 66.96979 | DB17: 89.05362 | DC17: 72.18811 | DD17: 60.29761 | DE17: 62.47507 | DF17: 51.56707
